Workbook
Name _________________________________________div1: #REF!
Name _______________________________s2: #REF!
Name ________________________UA1: #REF!
Name ________________________UA10: #REF!
Name ________________________UA2: #REF!
Name ________________________UA3: #REF!
Name ________________________UA4: #REF!
Name ________________________UA5: #REF!
Name ________________________UA6: #REF!
Name ________________________UA7: #REF!
Name ________________________UA8: #REF!
Name ________________________UA9: #REF!
Name _______________________UA1: #REF!
Name _______________________UA10: #REF!
Name _______________________UA2: #REF!
Name _______________________UA3: #REF!
Name _______________________UA4: #REF!
Name _______________________UA5: #REF!
Name _______________________UA6: #REF!
Name _______________________UA7: #REF!
Name _______________________UA8: #REF!
Name _______________________UA9: #REF!
Name ______________________div1: #REF!
Name ______________________UA1: #REF!
Name ______________________UA10: #REF!
Name ______________________UA2: #REF!
Name ______________________UA3: #REF!
Name ______________________UA4: #REF!
Name ______________________UA5: #REF!
Name ______________________UA6: #REF!
Name ______________________UA7: #REF!
Name ______________________UA8: #REF!
Name ______________________UA9: #REF!
Name _____________________div1: #REF!
Name _____________________UA1: #REF!
Name _____________________UA10: #REF!
Name _____________________UA2: #REF!
Name _____________________UA3: #REF!
Name _____________________UA4: #REF!
Name _____________________UA5: #REF!
Name _____________________UA6: #REF!
Name _____________________UA7: #REF!
Name _____________________UA8: #REF!
Name _____________________UA9: #REF!
Name ____________________div1: #REF!
Name ____________________s1: #REF!
Name ____________________UA1: #REF!
Name ____________________UA10: #REF!
Name ____________________UA2: #REF!
Name ____________________UA3: #REF!
Name ____________________UA4: #REF!
Name ____________________UA6: #REF!
Name ____________________UA7: #REF!
Name ____________________UA8: #REF!
Name ___________________UA1: #REF!
Name ___________________UA10: #REF!
Name ___________________UA2: #REF!
Name ___________________UA3: #REF!
Name ___________________UA4: #REF!
Name ___________________UA5: #REF!

Sheet 15.02.23 (ALL)
A1: Functional Loc. | B1: MaintPlant | C1: Model number | D1: StrIndicator | E1: FunctLocCat. | F1: Description | G1: SupFunctLoc. | H1: No. K A I | I1: Cost Center | J1: Planner group | K1: Main WorkCtr | L1: Catalog profile | M1: Start Point | N1: End Point | O1: Length | P1: User status | Q1: Kapasitas | R1: ManufSerialNo. | S1: Manufacturer | T1: System status
A2: AXL11468 | B2: B010 | C2: ZPD 43 | D2: KAIP2 | E2: L | F2: AXLE COUNTER ZP 60 BOO | G2: JAKBOOD01-THU1-ST_BOO-SDF001 | H2: AXC.ZP60.BOO | I2: 21022115 | J2: OSV | K2: S1.21 | L2: SE | M2: 54,678 | N2: 54,678 | O2: 0,000 | P2: TS BMN | S2: SIEMENS | T2: CRTE
A3: AXL11469 | B3: B010 | C3: ZPD 43 | D3: KAIP2 | E3: L | F3: AXLE COUNTER ZP 61 BOO | G3: JAKBOOD01-THU1-ST_BOO-SDF002 | H3: AXC.ZP61.BOO | I3: 21022115 | J3: OSV | K3: S1.21 | L3: SE | M3: 54,688 | N3: 54,688 | O3: 0,000 | P3: TS BMN | S3: SIEMENS | T3: CRTE
A4: AXL11470 | B4: B010 | C4: ZPD 43 | D4: KAIP2 | E4: L | F4: AXLE COUNTER ZP 62A BOO | G4: JAKBOOD01-THU1-ST_BOO-SDF003 | H4: AXC.ZP62A.BOO | I4: 21022115 | J4: OSV | K4: S1.21 | L4: SE | M4: 54,770 | N4: 54,770 | O4: 0,000 | P4: TS BMN | S4: SIEMENS | T4: CRTE
A5: AXL11471 | B5: B010 | C5: ZPD 43 | D5: KAIP2 | E5: L | F5: AXLE COUNTER ZP 42C BOO | G5: JAKBOOD01-THU1-ST_BOO-SDF004 | H5: AXC.ZP42C.BOO | I5: 21022115 | J5: OSV | K5: S1.21 | L5: SE | M5: 54,872 | N5: 54,872 | O5: 0,000 | P5: TS BMN | S5: SIEMENS | T5: CRTE
A6: AXL11472 | B6: B010 | C6: ZPD 43 | D6: KAIP2 | E6: L | F6: AXLE COUNTER ZP 41B BOO | G6: JAKBOOD01-THU1-ST_BOO-SDF005 | H6: AXC.ZP41B.BOO | I6: 21022115 | J6: OSV | K6: S1.21 | L6: SE | M6: 54,729 | N6: 54,729 | O6: 0,000 | P6: TS BMN | S6: SIEMENS | T6: CRTE
A7: AXL11473 | B7: B010 | C7: ZPD 43 | D7: KAIP2 | E7: L | F7: AXLE COUNTER ZP 42A BOO | G7: JAKBOOD01-THU1-ST_BOO-SDF006 | H7: AXC.ZP42A.BOO | I7: 21022115 | J7: OSV | K7: S1.21 | L7: SE | M7: 54,568 | N7: 54,568 | O7: 0,000 | P7: TS BMN | S7: SIEMENS | T7: CRTE
A8: AXL11474 | B8: B010 | C8: ZPD 43 | D8: KAIP2 | E8: L | F8: AXLE COUNTER ZP 42B BOO | G8: JAKBOOD01-THU1-ST_BOO-SDF007 | H8: AXC.ZP42B.BOO | I8: 21022115 | J8: OSV | K8: S1.21 | L8: SE | M8: 54,770 | N8: 54,770 | O8: 0,000 | P8: TS BMN | S8: SIEMENS | T8: CRTE
A9: AXL11475 | B9: B010 | C9: ZPD 43 | D9: KAIP2 | E9: L | F9: AXLE COUNTER ZP 62B BOO | G9: JAKBOOD01-THU1-ST_BOO-SDF008 | H9: AXC.ZP62B.BOO | I9: 21022115 | J9: OSV | K9: S1.21 | L9: SE | M9: 54,872 | N9: 54,872 | O9: 0,000 | P9: TS BMN | S9: SIEMENS | T9: CRTE
A10: AXL11476 | B10: B010 | C10: ZPD 43 | D10: KAIP2 | E10: L | F10: AXLE COUNTER ZP 23A BOO | G10: JAKBOOD01-THU1-ST_BOO-SDF009 | H10: AXC.ZP23A.BOO | I10: 21022115 | J10: OSV | K10: S1.21 | L10: SE | M10: 54,965 | N10: 54,965 | O10: 0,000 | P10: TS BMN | S10: SIEMENS | T10: CRTE
A11: AXL11477 | B11: B010 | C11: ZPD 43 | D11: KAIP2 | E11: L | F11: AXLE COUNTER ZP 23B BOO | G11: JAKBOOD01-THU1-ST_BOO-SDF010 | H11: AXC.ZP23B.BOO | I11: 21022115 | J11: OSV | K11: S1.21 | L11: SE | M11: 54,965 | N11: 54,965 | O11: 0,000 | P11: TS BMN | S11: SIEMENS | T11: CRTE
A12: AXL11478 | B12: B010 | C12: ZPD 43 | D12: KAIP2 | E12: L | F12: AXLE COUNTER ZP 24B BOO | G12: JAKBOOD01-THU1-ST_BOO-SDF011 | H12: AXC.ZP24B.BOO | I12: 21022115 | J12: OSV | K12: S1.21 | L12: SE | M12: 55,054 | N12: 55,054 | O12: 0,000 | P12: TS BMN | S12: SIEMENS | T12: CRTE
A13: AXL11479 | B13: B010 | C13: ZPD 43 | D13: KAIP2 | E13: L | F13: AXLE COUNTER ZP 24A BOO | G13: JAKBOOD01-THU1-ST_BOO-SDF012 | H13: AXC.ZP24A.BOO | I13: 21022115 | J13: OSV | K13: S1.21 | L13: SE | M13: 55,022 | N13: 55,022 | O13: 0,000 | P13: TS BMN | S13: SIEMENS | T13: CRTE
... A140: AXL11707 | B140: B010 | C140: ZPD 43 | D140: KAIP2 | E140: L | F140: AXLE COUNTER ZP 10B CLT | G140: JAKBOOD01-THU1-ST_CLT-SDF014 | H140: AXC.ZP10B.CLT | I140: 21022115 | J140: OSV | K140: S1.21 | L140: SE | M140: 47,087 | N140: 47,087 | O140: 0,000 | P140: TS BMN | S140: SIEMENS | T140: CRTE
A141: BOOYK_D01-THU1-ST_MSG-SBF006 | B141: B010 | D141: KAIL2 | E141: L | F141: SINYAL MASUK J10 MSG | G141: BOOYK_D01-THU1-ST_MSG | K141: S1.21 | L141: SE | M141: 13,685 | N141: 13,685 | O141: 0,000 | P141: ACT NOMA | T141: CRTE
A142: CDA10061 | B142: B010 | D142: KAIP2 | E142: L | F142: CATU DAYA ER SINYAL BOO | G142: ST_BOOD01-ER | H142: CD.ER.SYL.BOO | I142: 21022115 | J142: OSV | K142: S1.21 | L142: CD | M142: 54,886 | N142: 54,886 | O142: 0,000 | P142: TS BMN | T142: CRTE
A143: CDA10062 | B143: B010 | D143: KAIP2 | E143: L | F143: CATU DAYA ER SINYAL BOP | G143: ST_BOPD01-ER | H143: CD.ER.SYL.BOP | I143: 21022115 | J143: OSV | K143: S1.21 | L143: CD | M143: 0,450 | N143: 0,450 | O143: 0,000 | P143: TS BMN | T143: CRTE
A144: CDA10063 | B144: B010 | D144: KAIP2 | E144: L | F144: CATU DAYA ER SINYAL BTT | G144: ST_BTTD01-ER | H144: CD.ER.SYL.BTT | I144: 21022115 | J144: OSV | K144: S1.21 | L144: CD | M144: 4,378 | N144: 4,378 | O144: 0,000 | P144: TS BMN | T144: CRTE
A145: CDA10064 | B145: B010 | D145: KAIP2 | E145: L | F145: CATU DAYA ER SINYAL IB COS | G145: ST_CS_D01-ER | H145: CD.ER.SYL.IB.COS | I145: 21022115 | J145: OSV | K145: S1.21 | L145: CD | M145: 9,445 | N145: 9,445 | O145: 0,000 | P145: TS BMN | T145: CRTE
A146: CDA10065 | B146: B010 | D146: KAIP2 | E146: L | F146: CATU DAYA ER SINYAL MSG | G146: ST_MSGD01-ER | H146: CD.ER.SYL.MSG | I146: 21022115 | J146: OSV | K146: S1.21 | L146: CD | M146: 14,096 | N146: 14,096 | O146: 0,000 | P146: TS BMN | T146: CRTE
A147: CDA10066 | B147: B010 | D147: KAIP2 | E147: L | F147: CATU DAYA ER SINYAL IB CGB | G147: ST_CGBD01-ER | H147: CD.ER.SYL.IB.CGB | I147: 21022115 | J147: OSV | K147: S1.21 | L147: CD | M147: 19,620 | N147: 19,620 | O147: 0,000 | P147: TS BMN | T147: CRTE
A148: CDA10068 | B148: B010 | D148: KAIP2 | E148: L | F148: CATU DAYA ER RADIO CIOMAS | G148: ST_CS_D01-RAD | H148: CD.ER.RADIO.COS | I148: 21022115 | J148: OSV | K148: S1.21 | L148: CD | M148: 9,445 | N148: 9,445 | O148: 0,000 | P148: TS BMN | T148: CRTE
A149: CDA10069 | B149: B010 | D149: KAIP2 | E149: L | F149: CATU DAYA ER SINYAL CLT | G149: ST_CLTD01-ER | H149: CD.ER.SYL.CLT | I149: 21022115 | J149: OSV | K149: S1.21 | L149: CD | M149: 47,249 | N149: 47,249 | O149: 0,000 | P149: TS BMN | T149: CRTE
A150: CDA10070 | B150: B010 | D150: KAIP2 | E150: L | F150: GENSET ER SINYAL CLT | I150: 21022115 | J150: OSV | K150: S1.21 | L150: CD | M150: 47,249 | N150: 47,249 | O150: 0,000 | P150: SC BMN | S150: YANMAR | T150: INAC
A151: INB10008 | B151: B010 | D151: KAIP2 | E151: L | F151: KONTAK DETEKSI BTT DARI BOO | H151: KD.CDG-KEN | I151: 21022115 | J151: OSV | K151: S1.21 | L151: SM | P151: SC BMN | T151: INAC
A152: INB10238 | B152: B010 | D152: KAIP2 | E152: L | F152: CATU DAYA ER CLT | K152: S1.21 | M152: 0,000 | N152: 0,000 | O152: 0,000 | P152: SC BMN | T152: INAC
A153: INB10239 | B153: B010 | D153: KAIP2 | E153: L | F153: PANEL LCP CLT | H153: LCP.CLT | I153: 21022115 | J153: OSV | K153: S1.21 | L153: SE | P153: SC BMN | T153: INAC DLFL
A154: INB10240 | B154: B010 | D154: KAIP2 | E154: L | F154: INTERLOCKING ELEKTRIK SSI 10 BOO | K154: S1.21 | M154: 0,000 | N154: 0,000 | O154: 0,000 | P154: SC BMN | T154: INAC
A155: INB10241 | B155: B010 | D155: KAIP2 | E155: L | F155: INTERLOCKING ELEKTRIK SSI 11 BOO | K155: S1.21 | M155: 0,000 | N155: 0,000 | O155: 0,000 | P155: SC BMN | T155: INAC
A156: INB10242 | B156: B010 | D156: KAIP2 | E156: L | F156: DATA LOGGER BOO | K156: S1.21 | M156: 0,000 | N156: 0,000 | O156: 0,000 | P156: SC BMN | T156: INAC
A157: INB10243 | B157: B010 | D157: KAIP2 | E157: L | F157: CTS BOO | K157: S1.21 | M157: 0,000 | N157: 0,000 | O157: 0,000 | P157: SC BMN | T157: INAC
A158: INB10244 | B158: B010 | D158: KAIP2 | E158: L | F158: TECHNICIAN TERMINAL BOO | K158: S1.21 | M158: 0,000 | N158: 0,000 | O158: 0,000 | P158: SC BMN | T158: INAC
A159: INB10245 | B159: B010 | D159: KAIP2 | E159: L | F159: ER RACK A BOO | K159: S1.21 | M159: 0,000 | N159: 0,000 | O159: 0,000 | P159: SC BMN | T159: INAC
A160: INB10246 | B160: B010 | D160: KAIP2 | E160: L | F160: ER RACK B BOO | K160: S1.21 | M160: 0,000 | N160: 0,000 | O160: 0,000 | P160: SC BMN | T160: INAC
A161: INB10247 | B161: B010 | D161: KAIP2 | E161: L | F161: ER RACK C BOO | K161: S1.21 | M161: 0,000 | N161: 0,000 | O161: 0,000 | P161: SC BMN | T161: INAC
A162: INB10248 | B162: B010 | D162: KAIP2 | E162: L | F162: ER RACK D BOO | K162: S1.21 | M162: 0,000 | N162: 0,000 | O162: 0,000 | P162: SC BMN | T162: INAC
A163: INB10249 | B163: B010 | D163: KAIP2 | E163: L | F163: ER RACK E BOO | K163: S1.21 | M163: 0,000 | N163: 0,000 | O163: 0,000 | P163: SC BMN | T163: INAC
A164: INB10250 | B164: B010 | D164: KAIP2 | E164: L | F164: CATU DAYA ER BOO | K164: S1.21 | M164: 0,000 | N164: 0,000 | O164: 0,000 | P164: SC BMN | T164: INAC
A165: INB10251 | B165: B010 | C165: S&H | D165: KAIP2 | E165: L | F165: INTERLOCKING MEKANIK BTT | H165: ILM.BTT | I165: 21022115 | J165: OSV | K165: S1.21 | L165: SM | P165: SC BMN | S165: SIEMENS | T165: INAC DLFL
A166: INB10252 | B166: B010 | C166: S&H | D166: KAIP2 | E166: L | F166: INTERLOCKING MEKANIK MSG | H166: ILM.MSG | I166: 21022115 | J166: OSV | K166: S1.21 | L166: SM | P166: SC BMN | S166: SIEMENS | T166: INAC DLFL
...

Sheet CRTE
A1: Functional Loc. | B1: No. K A I | C1: Description | D1: Catalog profile | E1: Jenis Perawatan | F1: Lokasi | H1: TOTAL ASET | I1: 479
A2: AXL11468 | B2: AXC.ZP60.BOO | C2: AXLE COUNTER ZP 60 BOO | D2: SE | E2: Deteksi KA | F2: BOO
A3: AXL11469 | B3: AXC.ZP61.BOO | C3: AXLE COUNTER ZP 61 BOO | D3: SE | E3: Deteksi KA | F3: BOO
A4: AXL11470 | B4: AXC.ZP62A.BOO | C4: AXLE COUNTER ZP 62A BOO | D4: SE | E4: Deteksi KA | F4: BOO
A5: AXL11471 | B5: AXC.ZP42C.BOO | C5: AXLE COUNTER ZP 42C BOO | D5: SE | E5: Deteksi KA | F5: BOO
A6: AXL11472 | B6: AXC.ZP41B.BOO | C6: AXLE COUNTER ZP 41B BOO | D6: SE | E6: Deteksi KA | F6: BOO
A7: AXL11473 | B7: AXC.ZP42A.BOO | C7: AXLE COUNTER ZP 42A BOO | D7: SE | E7: Deteksi KA | F7: BOO
A8: AXL11474 | B8: AXC.ZP42B.BOO | C8: AXLE COUNTER ZP 42B BOO | D8: SE | E8: Deteksi KA | F8: BOO
A9: AXL11475 | B9: AXC.ZP62B.BOO | C9: AXLE COUNTER ZP 62B BOO | D9: SE | E9: Deteksi KA | F9: BOO
A10: AXL11476 | B10: AXC.ZP23A.BOO | C10: AXLE COUNTER ZP 23A BOO | D10: SE | E10: Deteksi KA | F10: BOO
A11: AXL11477 | B11: AXC.ZP23B.BOO | C11: AXLE COUNTER ZP 23B BOO | D11: SE | E11: Deteksi KA | F11: BOO
A12: AXL11478 | B12: AXC.ZP24B.BOO | C12: AXLE COUNTER ZP 24B BOO | D12: SE | E12: Deteksi KA | F12: BOO
A13: AXL11479 | B13: AXC.ZP24A.BOO | C13: AXLE COUNTER ZP 24A BOO | D13: SE | E13: Deteksi KA | F13: BOO
... A445: TRA11356 | B445: OTB.FO.JPL16.CGB | C445: OTB FO JPL 16 CGB | D445: MEDIA | E445: Pintu Perlintasan | F445: CGB
A446: TRA11368 | B446: FO.OTB.JPL.01.BOO | C446: OTB FO JPL 01 BOO | D446: MEDIA | E446: Double Aset
A447: TRA11369 | B447: FO.OTB.JPL.02.BOO | C447: OTB FO JPL 02 BOO | D447: MEDIA | E447: Double Aset
A448: TRA11370 | B448: FO.OTB.JPL.28.BOO.CLT | C448: OTB FO JPL 28 BOO -CLT | D448: MEDIA | E448: Double Aset
A449: TRA11371 | B449: FO.OTB.JPL.27.BOO.CLT | C449: OTB FO JPL 27 BOO -CLT | D449: MEDIA | E449: Double Aset
A450: TRA11372 | B450: FO.OTB.JPL.04.BOO.BOP | C450: OTB FO JPL 04 BOO-BOP | D450: MEDIA | E450: Double Aset
A451: TRA11373 | B451: FO.OTB.JPL.07.BOO.BOP | C451: OTB FO JPL 07 BOO-BOP | D451: MEDIA | E451: Double Aset
A452: TRA11374 | B452: FO.OTB.JPL.BNR.BOO.BOP | C452: OTB FO JPL BNR BOO-BOP | D452: MEDIA | E452: Double Aset
A453: TRA11375 | B453: FO.OTB.JPL.10.BOO.BOP | C453: OTB FO JPL 10 BTT | D453: MEDIA | E453: Double Aset
A454: TRA11376 | B454: FO.OTB.JPL.11.BOO.BOP | C454: OTB FO JPL 11 BTT | D454: MEDIA | E454: Double Aset
A455: TRA11377 | B455: FO.OTB.JPL.15.BOO.BOP | C455: OTB FO JPL 15 CGB | D455: MEDIA | E455: Double Aset
A456: TRA11378 | B456: FO.OTB.JPL.16.BOO.BOP | C456: OTB FO JPL 16 CGB | D456: MEDIA | E456: Double Aset
A457: TRA11379 | B457: FO.OTB.JPL.12.SF.BOO.BOP | C457: OTB FO JPL 12SF CGB | D457: MEDIA | E457: Double Aset
A458: TRA11380 | B458: FO.OTB.JPL.26N.CLT.BJD | C458: OTB FO JPL 26N CLT-BJD | D458: MEDIA | E458: Double Aset
A459: TWR10023 | B459: BANG.ER.R.BOO | C459: BANGUNAN ER RADIO BOO | D459: BANG | E459: PTDS | F459: BOO
A460: TWR10025 | B460: BANG.R.BOO | C460: BANGUNAN TOWER BOO | D460: BANG | E460: PTDS | F460: BOO
A461: TWR10052 | B461: TWR.RAD.COS | C461: TOWER RADIO CIOMAS | D461: TOWER | E461: PTDS | F461: COS
A462: WSL11073 | B462: W21A.BOO | C462: PENGGERAK WESEL W21A BOO | D462: SE | E462: Penggerak Wesel | F462: BOO
A463: WSL11074 | B463: W21B1.BOO | C463: PENGGERAK WESEL W21B1 BOO | D463: SE | E463: Penggerak Wesel | F463: BOO
A464: WSL11075 | B464: W21B2.BOO | C464: PENGGERAK WESEL W21B2 BOO | D464: SE | E464: Penggerak Wesel | F464: BOO
A465: WSL11076 | B465: W61A1.BOO | C465: PENGGERAK WESEL W61A1 BOO | D465: SE | E465: Penggerak Wesel | F465: BOO
A466: WSL11077 | B466: W61A2.BOO | C466: PENGGERAK WESEL W61A2 BOO | D466: SE | E466: Penggerak Wesel | F466: BOO
A467: WSL11078 | B467: W41.BOO | C467: PENGGERAK WESEL W41 BOO | D467: SE | E467: Penggerak Wesel | F467: BOO
A468: WSL11079 | B468: W43.BOO | C468: PENGGERAK WESEL W43 BOO | D468: SE | E468: Penggerak Wesel | F468: BOO
A469: WSL11080 | B469: W23A.BOO | C469: PENGGERAK WESEL W23A BOO | D469: SE | E469: Penggerak Wesel | F469: BOO
A470: WSL11081 | B470: W23B.BOO | C470: PENGGERAK WESEL W23B BOO | D470: SE | E470: Penggerak Wesel | F470: BOO
... A493: WSL11114 | B493: PW.23.CLT | C493: PENGGERAK WESEL W23 CLT | D493: SE | E493: Penggerak Wesel | F493: CLT

Sheet 04.06.23 (ALL)
A1: Functional Loc. | B1: MaintPlant | C1: Model number | D1: StrIndicator | E1: FunctLocCat. | F1: Description | G1: SupFunctLoc. | H1: No. K A I | I1: Cost Center | J1: Planner group | K1: Main WorkCtr | L1: Catalog profile | M1: Start Point | N1: End Point | O1: Length | P1: User status | Q1: Kapasitas | R1: ManufSerialNo. | S1: Manufacturer | T1: System status
A2: AXL11468 | B2: B010 | C2: ZPD 43 | D2: KAIP2 | E2: L | F2: AXLE COUNTER ZP 60 BOO | G2: JAKBOOD01-THU1-ST_BOO-SDF001 | H2: AXC.ZP60.BOO | I2: 21022115 | J2: OSV | K2: S1.21 | L2: SE | M2: 54,678 | N2: 54,678 | O2: 0,000 | P2: TS BMN | S2: SIEMENS | T2: CRTE
A3: AXL11469 | B3: B010 | C3: ZPD 43 | D3: KAIP2 | E3: L | F3: AXLE COUNTER ZP 61 BOO | G3: JAKBOOD01-THU1-ST_BOO-SDF002 | H3: AXC.ZP61.BOO | I3: 21022115 | J3: OSV | K3: S1.21 | L3: SE | M3: 54,688 | N3: 54,688 | O3: 0,000 | P3: TS BMN | S3: SIEMENS | T3: CRTE
A4: AXL11470 | B4: B010 | C4: ZPD 43 | D4: KAIP2 | E4: L | F4: AXLE COUNTER ZP 62A BOO | G4: JAKBOOD01-THU1-ST_BOO-SDF003 | H4: AXC.ZP62A.BOO | I4: 21022115 | J4: OSV | K4: S1.21 | L4: SE | M4: 54,770 | N4: 54,770 | O4: 0,000 | P4: TS BMN | S4: SIEMENS | T4: CRTE
A5: AXL11471 | B5: B010 | C5: ZPD 43 | D5: KAIP2 | E5: L | F5: AXLE COUNTER ZP 42C BOO | G5: JAKBOOD01-THU1-ST_BOO-SDF004 | H5: AXC.ZP42C.BOO | I5: 21022115 | J5: OSV | K5: S1.21 | L5: SE | M5: 54,872 | N5: 54,872 | O5: 0,000 | P5: TS BMN | S5: SIEMENS | T5: CRTE
A6: AXL11472 | B6: B010 | C6: ZPD 43 | D6: KAIP2 | E6: L | F6: AXLE COUNTER ZP 41B BOO | G6: JAKBOOD01-THU1-ST_BOO-SDF005 | H6: AXC.ZP41B.BOO | I6: 21022115 | J6: OSV | K6: S1.21 | L6: SE | M6: 54,729 | N6: 54,729 | O6: 0,000 | P6: TS BMN | S6: SIEMENS | T6: CRTE
A7: AXL11473 | B7: B010 | C7: ZPD 43 | D7: KAIP2 | E7: L | F7: AXLE COUNTER ZP 42A BOO | G7: JAKBOOD01-THU1-ST_BOO-SDF006 | H7: AXC.ZP42A.BOO | I7: 21022115 | J7: OSV | K7: S1.21 | L7: SE | M7: 54,568 | N7: 54,568 | O7: 0,000 | P7: TS BMN | S7: SIEMENS | T7: CRTE
A8: AXL11474 | B8: B010 | C8: ZPD 43 | D8: KAIP2 | E8: L | F8: AXLE COUNTER ZP 42B BOO | G8: JAKBOOD01-THU1-ST_BOO-SDF007 | H8: AXC.ZP42B.BOO | I8: 21022115 | J8: OSV | K8: S1.21 | L8: SE | M8: 54,770 | N8: 54,770 | O8: 0,000 | P8: TS BMN | S8: SIEMENS | T8: CRTE
A9: AXL11475 | B9: B010 | C9: ZPD 43 | D9: KAIP2 | E9: L | F9: AXLE COUNTER ZP 62B BOO | G9: JAKBOOD01-THU1-ST_BOO-SDF008 | H9: AXC.ZP62B.BOO | I9: 21022115 | J9: OSV | K9: S1.21 | L9: SE | M9: 54,872 | N9: 54,872 | O9: 0,000 | P9: TS BMN | S9: SIEMENS | T9: CRTE
A10: AXL11476 | B10: B010 | C10: ZPD 43 | D10: KAIP2 | E10: L | F10: AXLE COUNTER ZP 23A BOO | G10: JAKBOOD01-THU1-ST_BOO-SDF009 | H10: AXC.ZP23A.BOO | I10: 21022115 | J10: OSV | K10: S1.21 | L10: SE | M10: 54,965 | N10: 54,965 | O10: 0,000 | P10: TS BMN | S10: SIEMENS | T10: CRTE
A11: AXL11477 | B11: B010 | C11: ZPD 43 | D11: KAIP2 | E11: L | F11: AXLE COUNTER ZP 23B BOO | G11: JAKBOOD01-THU1-ST_BOO-SDF010 | H11: AXC.ZP23B.BOO | I11: 21022115 | J11: OSV | K11: S1.21 | L11: SE | M11: 54,965 | N11: 54,965 | O11: 0,000 | P11: TS BMN | S11: SIEMENS | T11: CRTE
A12: AXL11478 | B12: B010 | C12: ZPD 43 | D12: KAIP2 | E12: L | F12: AXLE COUNTER ZP 24B BOO | G12: JAKBOOD01-THU1-ST_BOO-SDF011 | H12: AXC.ZP24B.BOO | I12: 21022115 | J12: OSV | K12: S1.21 | L12: SE | M12: 55,054 | N12: 55,054 | O12: 0,000 | P12: TS BMN | S12: SIEMENS | T12: CRTE
A13: AXL11479 | B13: B010 | C13: ZPD 43 | D13: KAIP2 | E13: L | F13: AXLE COUNTER ZP 24A BOO | G13: JAKBOOD01-THU1-ST_BOO-SDF012 | H13: AXC.ZP24A.BOO | I13: 21022115 | J13: OSV | K13: S1.21 | L13: SE | M13: 55,022 | N13: 55,022 | O13: 0,000 | P13: TS BMN | S13: SIEMENS | T13: CRTE
... A140: AXL11707 | B140: B010 | C140: ZPD 43 | D140: KAIP2 | E140: L | F140: AXLE COUNTER ZP 10B CLT | G140: JAKBOOD01-THU1-ST_CLT-SDF014 | H140: AXC.ZP10B.CLT | I140: 21022115 | J140: OSV | K140: S1.21 | L140: SE | M140: 47,087 | N140: 47,087 | O140: 0,000 | P140: TS BMN | S140: SIEMENS | T140: CRTE
A141: BOOYK_D01-THU1-ST_MSG-SBF006 | B141: B010 | D141: KAIL2 | E141: L | F141: SINYAL MASUK J10 MSG | G141: BOOYK_D01-THU1-ST_MSG | K141: S1.21 | L141: SE | M141: 13,685 | N141: 13,685 | O141: 0,000 | P141: ACT NOMA | T141: CRTE
A142: CDA10061 | B142: B010 | D142: KAIP2 | E142: L | F142: CATU DAYA ER SINYAL BOO | G142: ST_BOOD01-ER | H142: CD.ER.SYL.BOO | I142: 21022115 | J142: OSV | K142: S1.21 | L142: CD | M142: 54,886 | N142: 54,886 | O142: 0,000 | P142: TS BMN | T142: CRTE
A143: CDA10062 | B143: B010 | D143: KAIP2 | E143: L | F143: CATU DAYA ER SINYAL BOP | G143: ST_BOPD01-ER | H143: CD.ER.SYL.BOP | I143: 21022115 | J143: OSV | K143: S1.21 | L143: CD | M143: 0,450 | N143: 0,450 | O143: 0,000 | P143: TS BMN | T143: CRTE
A144: CDA10063 | B144: B010 | D144: KAIP2 | E144: L | F144: CATU DAYA ER SINYAL BTT | G144: ST_BTTD01-ER | H144: CD.ER.SYL.BTT | I144: 21022115 | J144: OSV | K144: S1.21 | L144: CD | M144: 4,378 | N144: 4,378 | O144: 0,000 | P144: TS BMN | T144: CRTE
A145: CDA10064 | B145: B010 | D145: KAIP2 | E145: L | F145: CATU DAYA ER SINYAL IB COS | G145: ST_CS_D01-ER | H145: CD.ER.SYL.IB.COS | I145: 21022115 | J145: OSV | K145: S1.21 | L145: CD | M145: 9,445 | N145: 9,445 | O145: 0,000 | P145: TS BMN | T145: CRTE
A146: CDA10065 | B146: B010 | D146: KAIP2 | E146: L | F146: CATU DAYA ER SINYAL MSG | G146: ST_MSGD01-ER | H146: CD.ER.SYL.MSG | I146: 21022115 | J146: OSV | K146: S1.21 | L146: CD | M146: 14,096 | N146: 14,096 | O146: 0,000 | P146: TS BMN | T146: CRTE
A147: CDA10066 | B147: B010 | D147: KAIP2 | E147: L | F147: CATU DAYA ER SINYAL IB CGB | G147: ST_CGBD01-ER | H147: CD.ER.SYL.IB.CGB | I147: 21022115 | J147: OSV | K147: S1.21 | L147: CD | M147: 19,620 | N147: 19,620 | O147: 0,000 | P147: TS BMN | T147: CRTE
A148: CDA10068 | B148: B010 | D148: KAIP2 | E148: L | F148: CATU DAYA ER RADIO CIOMAS | G148: ST_CS_D01-RAD | H148: CD.ER.RADIO.COS | I148: 21022115 | J148: OSV | K148: S1.21 | L148: CD | M148: 9,445 | N148: 9,445 | O148: 0,000 | P148: TS BMN | T148: CRTE
A149: CDA10069 | B149: B010 | D149: KAIP2 | E149: L | F149: CATU DAYA ER SINYAL CLT | G149: ST_CLTD01-ER | H149: CD.ER.SYL.CLT | I149: 21022115 | J149: OSV | K149: S1.21 | L149: CD | M149: 47,249 | N149: 47,249 | O149: 0,000 | P149: TS BMN | T149: CRTE
A150: CDA10070 | B150: B010 | D150: KAIP2 | E150: L | F150: GENSET ER SINYAL CLT | I150: 21022115 | J150: OSV | K150: S1.21 | L150: CD | M150: 47,249 | N150: 47,249 | O150: 0,000 | P150: SC BMN | S150: YANMAR | T150: INAC
A151: INB10008 | B151: B010 | D151: KAIP2 | E151: L | F151: KONTAK DETEKSI BTT DARI BOO | H151: KD.CDG-KEN | I151: 21022115 | J151: OSV | K151: S1.21 | L151: SM | P151: SC BMN | T151: INAC
A152: INB10238 | B152: B010 | D152: KAIP2 | E152: L | F152: CATU DAYA ER CLT | K152: S1.21 | M152: 0,000 | N152: 0,000 | O152: 0,000 | P152: SC BMN | T152: INAC
A153: INB10239 | B153: B010 | D153: KAIP2 | E153: L | F153: PANEL LCP CLT | H153: LCP.CLT | I153: 21022115 | J153: OSV | K153: S1.21 | L153: SE | P153: SC BMN | T153: INAC DLFL
A154: INB10240 | B154: B010 | D154: KAIP2 | E154: L | F154: INTERLOCKING ELEKTRIK SSI 10 BOO | K154: S1.21 | M154: 0,000 | N154: 0,000 | O154: 0,000 | P154: SC BMN | T154: INAC
A155: INB10241 | B155: B010 | D155: KAIP2 | E155: L | F155: INTERLOCKING ELEKTRIK SSI 11 BOO | K155: S1.21 | M155: 0,000 | N155: 0,000 | O155: 0,000 | P155: SC BMN | T155: INAC
A156: INB10242 | B156: B010 | D156: KAIP2 | E156: L | F156: DATA LOGGER BOO | K156: S1.21 | M156: 0,000 | N156: 0,000 | O156: 0,000 | P156: SC BMN | T156: INAC
A157: INB10243 | B157: B010 | D157: KAIP2 | E157: L | F157: CTS BOO | K157: S1.21 | M157: 0,000 | N157: 0,000 | O157: 0,000 | P157: SC BMN | T157: INAC
A158: INB10244 | B158: B010 | D158: KAIP2 | E158: L | F158: TECHNICIAN TERMINAL BOO | K158: S1.21 | M158: 0,000 | N158: 0,000 | O158: 0,000 | P158: SC BMN | T158: INAC
A159: INB10245 | B159: B010 | D159: KAIP2 | E159: L | F159: ER RACK A BOO | K159: S1.21 | M159: 0,000 | N159: 0,000 | O159: 0,000 | P159: SC BMN | T159: INAC
A160: INB10246 | B160: B010 | D160: KAIP2 | E160: L | F160: ER RACK B BOO | K160: S1.21 | M160: 0,000 | N160: 0,000 | O160: 0,000 | P160: SC BMN | T160: INAC
A161: INB10247 | B161: B010 | D161: KAIP2 | E161: L | F161: ER RACK C BOO | K161: S1.21 | M161: 0,000 | N161: 0,000 | O161: 0,000 | P161: SC BMN | T161: INAC
A162: INB10248 | B162: B010 | D162: KAIP2 | E162: L | F162: ER RACK D BOO | K162: S1.21 | M162: 0,000 | N162: 0,000 | O162: 0,000 | P162: SC BMN | T162: INAC
A163: INB10249 | B163: B010 | D163: KAIP2 | E163: L | F163: ER RACK E BOO | K163: S1.21 | M163: 0,000 | N163: 0,000 | O163: 0,000 | P163: SC BMN | T163: INAC
A164: INB10250 | B164: B010 | D164: KAIP2 | E164: L | F164: CATU DAYA ER BOO | K164: S1.21 | M164: 0,000 | N164: 0,000 | O164: 0,000 | P164: SC BMN | T164: INAC
A165: INB10251 | B165: B010 | C165: S&H | D165: KAIP2 | E165: L | F165: INTERLOCKING MEKANIK BTT | H165: ILM.BTT | I165: 21022115 | J165: OSV | K165: S1.21 | L165: SM | P165: SC BMN | S165: SIEMENS | T165: INAC DLFL
A166: INB10252 | B166: B010 | C166: S&H | D166: KAIP2 | E166: L | F166: INTERLOCKING MEKANIK MSG | H166: ILM.MSG | I166: 21022115 | J166: OSV | K166: S1.21 | L166: SM | P166: SC BMN | S166: SIEMENS | T166: INAC DLFL
...

Sheet CRTE REV.
A1: Functional Loc. | B1: No. K A I | C1: Description | D1: Catalog profile | E1: Jenis Perawatan | F1: Lokasi | H1: TOTAL ASET | I1: 484 | J1: =I1+31 -> 515 | K1: =J1-11-17 -> 487
A2: AXL11468 | B2: AXC.ZP60.BOO | C2: AXLE COUNTER ZP 60 BOO | D2: SE | F2: boo | G2: =VLOOKUP(A2,CRTE!$A$2:$F$493,1,0) -> AXL11468
A3: AXL11469 | B3: AXC.ZP61.BOO | C3: AXLE COUNTER ZP 61 BOO | D3: SE | F3: boo | G3: =VLOOKUP(A3,CRTE!$A$2:$F$493,1,0) -> AXL11469
A4: AXL11470 | B4: AXC.ZP62A.BOO | C4: AXLE COUNTER ZP 62A BOO | D4: SE | F4: boo | G4: =VLOOKUP(A4,CRTE!$A$2:$F$493,1,0) -> AXL11470
A5: AXL11471 | B5: AXC.ZP42C.BOO | C5: AXLE COUNTER ZP 42C BOO | D5: SE | F5: boo | G5: =VLOOKUP(A5,CRTE!$A$2:$F$493,1,0) -> AXL11471
A6: AXL11472 | B6: AXC.ZP41B.BOO | C6: AXLE COUNTER ZP 41B BOO | D6: SE | F6: boo | G6: =VLOOKUP(A6,CRTE!$A$2:$F$493,1,0) -> AXL11472
A7: AXL11473 | B7: AXC.ZP42A.BOO | C7: AXLE COUNTER ZP 42A BOO | D7: SE | F7: boo | G7: =VLOOKUP(A7,CRTE!$A$2:$F$493,1,0) -> AXL11473
A8: AXL11474 | B8: AXC.ZP42B.BOO | C8: AXLE COUNTER ZP 42B BOO | D8: SE | F8: boo | G8: =VLOOKUP(A8,CRTE!$A$2:$F$493,1,0) -> AXL11474
A9: AXL11475 | B9: AXC.ZP62B.BOO | C9: AXLE COUNTER ZP 62B BOO | D9: SE | F9: boo | G9: =VLOOKUP(A9,CRTE!$A$2:$F$493,1,0) -> AXL11475
A10: AXL11476 | B10: AXC.ZP23A.BOO | C10: AXLE COUNTER ZP 23A BOO | D10: SE | F10: boo | G10: =VLOOKUP(A10,CRTE!$A$2:$F$493,1,0) -> AXL11476
A11: AXL11477 | B11: AXC.ZP23B.BOO | C11: AXLE COUNTER ZP 23B BOO | D11: SE | F11: boo | G11: =VLOOKUP(A11,CRTE!$A$2:$F$493,1,0) -> AXL11477
A12: AXL11478 | B12: AXC.ZP24B.BOO | C12: AXLE COUNTER ZP 24B BOO | D12: SE | F12: boo | G12: =VLOOKUP(A12,CRTE!$A$2:$F$493,1,0) -> AXL11478
A13: AXL11479 | B13: AXC.ZP24A.BOO | C13: AXLE COUNTER ZP 24A BOO | D13: SE | F13: boo | G13: =VLOOKUP(A13,CRTE!$A$2:$F$493,1,0) -> AXL11479
... A485: WSL11114 | B485: PW.23.CLT | C485: PENGGERAK WESEL W23 CLT | D485: SE | F485: clt | G485: =VLOOKUP(A485,CRTE!$A$2:$F$493,1,0) -> WSL11114

Sheet 24.11.23 (ALL)
A1: Functional Loc. | B1: StrIndicator | C1: FunctLocCat. | D1: Description | E1: MaintPlant | F1: No. K A I | G1: Manufacturer | H1: Model number | I1: Kapasitas | J1: ManufSerialNo. | K1: Cost Center | L1: Asset | M1: Planner group | N1: Main WorkCtr | O1: Catalog profile | P1: No. Material | Q1: Start Point | R1: End Point | S1: Length | T1: SupFunctLoc. | U1: Position | V1: System status | W1: User status | X1: Mulai Dinas | Y1: Size/dimensions | Z1: Weight unit
A2: AXL11468 | B2: KAIP2 | C2: L | D2: AXLE COUNTER ZP 60 BOO | E2: B010 | F2: AXC.ZP60.BOO | G2: SIEMENS | H2: ZPD 43 | K2: 21022115 | M2: OSV | N2: S1.21 | O2: SE | Q2: 54,678 | R2: 54,678 | S2: 0,000 | T2: JAKBOOD01-THU1-ST_BOO-SDF001 | U2: 0010 | V2: CRTE | W2: TS BMN | X2: 44650
A3: AXL11469 | B3: KAIP2 | C3: L | D3: AXLE COUNTER ZP 61 BOO | E3: B010 | F3: AXC.ZP61.BOO | G3: SIEMENS | H3: ZPD 43 | K3: 21022115 | M3: OSV | N3: S1.21 | O3: SE | Q3: 54,688 | R3: 54,688 | S3: 0,000 | T3: JAKBOOD01-THU1-ST_BOO-SDF002 | U3: 0010 | V3: CRTE | W3: TS BMN | X3: 44650
A4: AXL11470 | B4: KAIP2 | C4: L | D4: AXLE COUNTER ZP 62A BOO | E4: B010 | F4: AXC.ZP62A.BOO | G4: SIEMENS | H4: ZPD 43 | K4: 21022115 | M4: OSV | N4: S1.21 | O4: SE | Q4: 54,770 | R4: 54,770 | S4: 0,000 | T4: JAKBOOD01-THU1-ST_BOO-SDF003 | U4: 0010 | V4: CRTE | W4: TS BMN | X4: 44650
A5: AXL11471 | B5: KAIP2 | C5: L | D5: AXLE COUNTER ZP 42C BOO | E5: B010 | F5: AXC.ZP42C.BOO | G5: SIEMENS | H5: ZPD 43 | K5: 21022115 | M5: OSV | N5: S1.21 | O5: SE | Q5: 54,872 | R5: 54,872 | S5: 0,000 | T5: JAKBOOD01-THU1-ST_BOO-SDF004 | U5: 0010 | V5: CRTE | W5: TS BMN | X5: 44650
A6: AXL11472 | B6: KAIP2 | C6: L | D6: AXLE COUNTER ZP 41B BOO | E6: B010 | F6: AXC.ZP41B.BOO | G6: SIEMENS | H6: ZPD 43 | K6: 21022115 | M6: OSV | N6: S1.21 | O6: SE | Q6: 54,729 | R6: 54,729 | S6: 0,000 | T6: JAKBOOD01-THU1-ST_BOO-SDF005 | U6: 0010 | V6: CRTE | W6: TS BMN | X6: 44650
A7: AXL11473 | B7: KAIP2 | C7: L | D7: AXLE COUNTER ZP 42A BOO | E7: B010 | F7: AXC.ZP42A.BOO | G7: SIEMENS | H7: ZPD 43 | K7: 21022115 | M7: OSV | N7: S1.21 | O7: SE | Q7: 54,568 | R7: 54,568 | S7: 0,000 | T7: JAKBOOD01-THU1-ST_BOO-SDF006 | U7: 0010 | V7: CRTE | W7: TS BMN | X7: 44650
A8: AXL11474 | B8: KAIP2 | C8: L | D8: AXLE COUNTER ZP 42B BOO | E8: B010 | F8: AXC.ZP42B.BOO | G8: SIEMENS | H8: ZPD 43 | K8: 21022115 | M8: OSV | N8: S1.21 | O8: SE | Q8: 54,770 | R8: 54,770 | S8: 0,000 | T8: JAKBOOD01-THU1-ST_BOO-SDF007 | U8: 0010 | V8: CRTE | W8: TS BMN | X8: 44650
A9: AXL11475 | B9: KAIP2 | C9: L | D9: AXLE COUNTER ZP 62B BOO | E9: B010 | F9: AXC.ZP62B.BOO | G9: SIEMENS | H9: ZPD 43 | K9: 21022115 | M9: OSV | N9: S1.21 | O9: SE | Q9: 54,872 | R9: 54,872 | S9: 0,000 | T9: JAKBOOD01-THU1-ST_BOO-SDF008 | U9: 0010 | V9: CRTE | W9: TS BMN | X9: 44650
A10: AXL11476 | B10: KAIP2 | C10: L | D10: AXLE COUNTER ZP 23A BOO | E10: B010 | F10: AXC.ZP23A.BOO | G10: SIEMENS | H10: ZPD 43 | K10: 21022115 | M10: OSV | N10: S1.21 | O10: SE | Q10: 54,965 | R10: 54,965 | S10: 0,000 | T10: JAKBOOD01-THU1-ST_BOO-SDF009 | U10: 0010 | V10: CRTE | W10: TS BMN | X10: 44650
A11: AXL11477 | B11: KAIP2 | C11: L | D11: AXLE COUNTER ZP 23B BOO | E11: B010 | F11: AXC.ZP23B.BOO | G11: SIEMENS | H11: ZPD 43 | K11: 21022115 | M11: OSV | N11: S1.21 | O11: SE | Q11: 54,965 | R11: 54,965 | S11: 0,000 | T11: JAKBOOD01-THU1-ST_BOO-SDF010 | U11: 0010 | V11: CRTE | W11: TS BMN | X11: 44650
A12: AXL11478 | B12: KAIP2 | C12: L | D12: AXLE COUNTER ZP 24B BOO | E12: B010 | F12: AXC.ZP24B.BOO | G12: SIEMENS | H12: ZPD 43 | K12: 21022115 | M12: OSV | N12: S1.21 | O12: SE | Q12: 55,054 | R12: 55,054 | S12: 0,000 | T12: JAKBOOD01-THU1-ST_BOO-SDF011 | U12: 0010 | V12: CRTE | W12: TS BMN | X12: 44650
A13: AXL11479 | B13: KAIP2 | C13: L | D13: AXLE COUNTER ZP 24A BOO | E13: B010 | F13: AXC.ZP24A.BOO | G13: SIEMENS | H13: ZPD 43 | K13: 21022115 | M13: OSV | N13: S1.21 | O13: SE | Q13: 55,022 | R13: 55,022 | S13: 0,000 | T13: JAKBOOD01-THU1-ST_BOO-SDF012 | U13: 0010 | V13: CRTE | W13: TS BMN | X13: 44650
... A140: AXL11707 | B140: KAIP2 | C140: L | D140: AXLE COUNTER ZP 10B CLT | E140: B010 | F140: AXC.ZP10B.CLT | G140: SIEMENS | H140: ZPD 43 | K140: 21022115 | M140: OSV | N140: S1.21 | O140: SE | Q140: 47,087 | R140: 47,087 | S140: 0,000 | T140: JAKBOOD01-THU1-ST_CLT-SDF014 | U140: 0010 | V140: CRTE | W140: TS BMN | X140: 44819
A141: BOOYK_D01-THU1-ST_MSG-SBF006 | B141: KAIL2 | C141: L | D141: SINYAL MASUK J10 MSG | E141: B010 | N141: S1.21 | O141: SE | Q141: 0,000 | R141: 0,000 | S141: 0,000 | V141: CRTE | W141: ACT NOMA | X141: 44660
A142: CDA10061 | B142: KAIP2 | C142: L | D142: CATU DAYA ER SINYAL BOO | E142: B010 | N142: S1.21 | O142: CD | Q142: 0,000 | R142: 0,000 | S142: 0,000 | U142: 0010 | V142: CRTE | W142: SC BMN | X142: 44650
A143: CDA10062 | B143: KAIP2 | C143: L | D143: CATU DAYA ER SINYAL BOP | E143: B010 | N143: S1.21 | O143: CD | Q143: 0,000 | R143: 0,000 | S143: 0,000 | U143: 0010 | V143: CRTE | W143: SC BMN | X143: 44660
A144: CDA10063 | B144: KAIP2 | C144: L | D144: CATU DAYA ER SINYAL BTT | E144: B010 | N144: S1.21 | O144: CD | Q144: 0,000 | R144: 0,000 | S144: 0,000 | U144: 0010 | V144: CRTE | W144: SC BMN | X144: 44660
A145: CDA10064 | B145: KAIP2 | C145: L | D145: CATU DAYA ER SINYAL IB COS | E145: B010 | N145: S1.21 | O145: CD | Q145: 0,000 | R145: 0,000 | S145: 0,000 | U145: 0010 | V145: CRTE | W145: SC BMN | X145: 44660
A146: CDA10065 | B146: KAIP2 | C146: L | D146: CATU DAYA ER SINYAL MSG | E146: B010 | N146: S1.21 | O146: CD | Q146: 0,000 | R146: 0,000 | S146: 0,000 | U146: 0010 | V146: CRTE | W146: SC BMN | X146: 44660
A147: CDA10066 | B147: KAIP2 | C147: L | D147: CATU DAYA ER SINYAL IB CGB | E147: B010 | N147: S1.21 | O147: CD | Q147: 0,000 | R147: 0,000 | S147: 0,000 | U147: 0010 | V147: CRTE | W147: SC BMN | X147: 44660
A148: CDA10068 | B148: KAIP2 | C148: L | D148: CATU DAYA ER RADIO CIOMAS | E148: B010 | N148: S1.21 | O148: CD | Q148: 0,000 | R148: 0,000 | S148: 0,000 | U148: 0010 | V148: CRTE | W148: SC BMN | X148: 44660
A149: CDA10069 | B149: KAIP2 | C149: L | D149: CATU DAYA ER SINYAL CLT | E149: B010 | N149: S1.21 | O149: CD | Q149: 0,000 | R149: 0,000 | S149: 0,000 | U149: 0010 | V149: CRTE | W149: SC BMN | X149: 44819
A150: CDA10070 | B150: KAIP2 | C150: L | D150: GENSET ER SINYAL CLT | E150: B010 | G150: YANMAR | K150: 21022115 | M150: OSV | N150: S1.21 | O150: CD | Q150: 47,249 | R150: 47,249 | S150: 0,000 | U150: 0010 | V150: INAC | W150: SC BMN | X150: 44819
A151: CDA10136 | B151: KAIP2 | C151: L | D151: GENSET ER RADIO BOO | E151: B010 | F151: GST.RXX.BOO | G151: BISMA | I151: 15 KVA | K151: 21022115 | M151: OSV | N151: S1.21 | O151: CD | Q151: 54,700 | R151: 54,700 | S151: 0,000 | T151: ST_BOOD01-BR | U151: 0010 | V151: CRTE | W151: TS BMN | X151: 32874
A152: CDA10137 | B152: KAIP2 | C152: L | D152: GENSET ER RADIO CS | E152: B010 | F152: GST.ER.RADIO.COS | G152: YANMAR | I152: 6 KVA | K152: 21022115 | M152: OSV | N152: S1.21 | O152: CD | Q152: 9,445 | R152: 9,445 | S152: 0,000 | T152: ST_CS_D01-BR | U152: 0010 | V152: CRTE | W152: TS BMN | X152: 44660
A153: CDA10145 | B153: KAIP2 | C153: L | D153: GENSET ER SINYAL BOO | E153: B010 | F153: GST.ER.SYL.BOO | G153: YANMAR | I153: 40 KVA | K153: 21022115 | M153: OSV | N153: S1.21 | O153: CD | Q153: 54,886 | R153: 54,886 | S153: 0,000 | T153: ST_BOOD01-ER | U153: 0010 | V153: CRTE | W153: TS BMN | X153: 44650
A154: CDA10146 | B154: KAIP2 | C154: L | D154: GENSET ER SINYAL BOP | E154: B010 | F154: GST.ER.RADIO.BOP | G154: YANMAR | I154: 15KVA | K154: 21022115 | M154: OSV | N154: S1.21 | O154: CD | Q154: 0,450 | R154: 0,450 | S154: 0,000 | T154: ST_BOOD01-ER | U154: 0010 | V154: CRTE | W154: TS BMN | X154: 44660
A155: CDA10147 | B155: KAIP2 | C155: L | D155: GENSET ER SINYAL BTT | E155: B010 | F155: GST.ER.SYL.BTT | G155: YANMAR | I155: 20KVA | K155: 21022115 | M155: OSV | N155: S1.21 | O155: CD | Q155: 4,378 | R155: 4,378 | S155: 0,000 | T155: ST_BTTD01-ER | U155: 0010 | V155: CRTE | W155: TS BMN | X155: 44660
A156: CDA10148 | B156: KAIP2 | C156: L | D156: GENSET ER SINYAL CGB | E156: B010 | F156: GST.ER.SYL.IB.CGB | G156: YANMAR | I156: 6 KVA | K156: 21022115 | M156: OSV | N156: S1.21 | O156: CD | Q156: 19,620 | R156: 19,620 | S156: 0,000 | T156: ST_CGBD01-ER | U156: 0010 | V156: CRTE | W156: TS BMN | X156: 44660
A157: CDA10150 | B157: KAIP2 | C157: L | D157: GENSET ER SINYAL CS | E157: B010 | F157: GST.ER.SYL.IB.COM | G157: YANMAR | I157: 6 KVA | K157: 21022115 | M157: OSV | N157: S1.21 | O157: CD | Q157: 9,445 | R157: 9,445 | S157: 0,000 | T157: ST_CS_D01-ER | U157: 0010 | V157: CRTE | W157: TS BMN | X157: 44660
A158: CDA10151 | B158: KAIP2 | C158: L | D158: GENSET ER SINYAL CLT | E158: B010 | F158: GST.ER.SYL.CLT | G158: YANMAR | I158: 40 KVA | K158: 21022115 | M158: OSV | N158: S1.21 | O158: CD | Q158: 47,249 | R158: 47,249 | S158: 0,000 | T158: ST_CLTD01-ER | U158: 0010 | V158: CRTE | W158: TS BMN | X158: 44819
A159: CDA10154 | B159: KAIP2 | C159: L | D159: GENSET ER SINYAL MSG | E159: B010 | F159: GST.ER.SYL.MSG | G159: YANMAR | I159: 15 KVA | K159: 21022115 | M159: OSV | N159: S1.21 | O159: CD | Q159: 14,096 | R159: 14,096 | S159: 0,000 | T159: ST_MSGD01-ER | U159: 0010 | V159: CRTE | W159: TS BMN | X159: 44660
A160: CDA10246 | B160: KAIP2 | C160: L | D160: UPS ER RADIO BOO | E160: B010 | F160: UPS.RXX.BOO | G160: PILLER | I160: 20 KVA | K160: 21022115 | M160: OSV | N160: S1.21 | O160: CD | Q160: 54,700 | R160: 54,700 | S160: 0,000 | T160: ST_BOOD01-BR | U160: 0010 | V160: CRTE | W160: TS BMN | X160: 32874
A161: CDA10247 | B161: KAIP2 | C161: L | D161: UPS ER RADIO CS | E161: B010 | F161: UPS.ER.RADIO.COS | G161: PILLER | I161: 5 KVA | K161: 21022115 | M161: OSV | N161: S1.21 | O161: CD | Q161: 9,445 | R161: 9,445 | S161: 0,000 | T161: ST_CS_D01-BR | U161: 0010 | V161: CRTE | W161: TS BMN | X161: 44660
A162: CDA10251 | B162: KAIP2 | C162: L | D162: UPS ER SINYAL BOO | E162: B010 | F162: UPS.ER.SYL.BOO | G162: PILLER | I162: 40 KVA | K162: 21022115 | M162: OSV | N162: S1.21 | O162: CD | Q162: 54,886 | R162: 54,886 | S162: 0,000 | T162: ST_BOOD01-ER | U162: 0010 | V162: CRTE | W162: TS BMN | X162: 44650
... A177: CDA10396 | B177: KAIP2 | C177: L | D177: BATTERE ER SINYAL MSG | E177: B010 | F177: BATT.ER.SYL.MSG | G177: GENESIS | I177: 40/12V/100AH | K177: 21022115 | M177: OSV | N177: S1.21 | O177: CD | Q177: 14,096 | R177: 14,096 | S177: 0,000 | T177: ST_MSGD01-ER | U177: 0010 | V177: CRTE | W177: TS BMN | X177: 44660
A178: INB10008 | B178: KAIP2 | C178: L | D178: KONTAK DETEKSI BTT DARI BOO | E178: B010 | F178: KD.CDG-KEN | K178: 21022115 | M178: OSV | N178: S1.21 | O178: SM | V178: INAC | W178: SC BMN
A179: INB10238 | B179: KAIP2 | C179: L | D179: CATU DAYA ER CLT | E179: B010 | N179: S1.21 | Q179: 0,000 | R179: 0,000 | S179: 0,000 | U179: 10 | V179: INAC | W179: SC BMN
A180: INB10239 | B180: KAIP2 | C180: L | D180: PANEL LCP CLT | E180: B010 | F180: LCP.CLT | K180: 21022115 | M180: OSV | N180: S1.21 | O180: SE | V180: INAC DLFL | W180: SC BMN
...

Sheet CRTE REV.2
A1: Functional Loc. | B1: No. K A I | C1: Description | D1: Catalog profile | E1: System status | F1: Cek aset baru | H1: Cek perubahan deskripsi
A2: AXL11468 | B2: AXC.ZP60.BOO | C2: AXLE COUNTER ZP 60 BOO | D2: SE | E2: CRTE | F2: =VLOOKUP(A2,'CRTE REV.'!$A$2:$C$485,1,0) -> AXL11468 | H2: =VLOOKUP(A2,'CRTE REV.'!$A$2:$C$485,3,0) -> AXLE COUNTER ZP 60 BOO
A3: AXL11469 | B3: AXC.ZP61.BOO | C3: AXLE COUNTER ZP 61 BOO | D3: SE | E3: CRTE | F3: =VLOOKUP(A3,'CRTE REV.'!$A$2:$C$485,1,0) -> AXL11469 | H3: =VLOOKUP(A3,'CRTE REV.'!$A$2:$C$485,3,0) -> AXLE COUNTER ZP 61 BOO
A4: AXL11470 | B4: AXC.ZP62A.BOO | C4: AXLE COUNTER ZP 62A BOO | D4: SE | E4: CRTE | F4: =VLOOKUP(A4,'CRTE REV.'!$A$2:$C$485,1,0) -> AXL11470 | H4: =VLOOKUP(A4,'CRTE REV.'!$A$2:$C$485,3,0) -> AXLE COUNTER ZP 62A BOO
A5: AXL11471 | B5: AXC.ZP42C.BOO | C5: AXLE COUNTER ZP 42C BOO | D5: SE | E5: CRTE | F5: =VLOOKUP(A5,'CRTE REV.'!$A$2:$C$485,1,0) -> AXL11471 | H5: =VLOOKUP(A5,'CRTE REV.'!$A$2:$C$485,3,0) -> AXLE COUNTER ZP 42C BOO
A6: AXL11472 | B6: AXC.ZP41B.BOO | C6: AXLE COUNTER ZP 41B BOO | D6: SE | E6: CRTE | F6: =VLOOKUP(A6,'CRTE REV.'!$A$2:$C$485,1,0) -> AXL11472 | H6: =VLOOKUP(A6,'CRTE REV.'!$A$2:$C$485,3,0) -> AXLE COUNTER ZP 41B BOO
A7: AXL11473 | B7: AXC.ZP42A.BOO | C7: AXLE COUNTER ZP 42A BOO | D7: SE | E7: CRTE | F7: =VLOOKUP(A7,'CRTE REV.'!$A$2:$C$485,1,0) -> AXL11473 | H7: =VLOOKUP(A7,'CRTE REV.'!$A$2:$C$485,3,0) -> AXLE COUNTER ZP 42A BOO
A8: AXL11474 | B8: AXC.ZP42B.BOO | C8: AXLE COUNTER ZP 42B BOO | D8: SE | E8: CRTE | F8: =VLOOKUP(A8,'CRTE REV.'!$A$2:$C$485,1,0) -> AXL11474 | H8: =VLOOKUP(A8,'CRTE REV.'!$A$2:$C$485,3,0) -> AXLE COUNTER ZP 42B BOO
A9: AXL11475 | B9: AXC.ZP62B.BOO | C9: AXLE COUNTER ZP 62B BOO | D9: SE | E9: CRTE | F9: =VLOOKUP(A9,'CRTE REV.'!$A$2:$C$485,1,0) -> AXL11475 | H9: =VLOOKUP(A9,'CRTE REV.'!$A$2:$C$485,3,0) -> AXLE COUNTER ZP 62B BOO
A10: AXL11476 | B10: AXC.ZP23A.BOO | C10: AXLE COUNTER ZP 23A BOO | D10: SE | E10: CRTE | F10: =VLOOKUP(A10,'CRTE REV.'!$A$2:$C$485,1,0) -> AXL11476 | H10: =VLOOKUP(A10,'CRTE REV.'!$A$2:$C$485,3,0) -> AXLE COUNTER ZP 23A BOO
A11: AXL11477 | B11: AXC.ZP23B.BOO | C11: AXLE COUNTER ZP 23B BOO | D11: SE | E11: CRTE | F11: =VLOOKUP(A11,'CRTE REV.'!$A$2:$C$485,1,0) -> AXL11477 | H11: =VLOOKUP(A11,'CRTE REV.'!$A$2:$C$485,3,0) -> AXLE COUNTER ZP 23B BOO
A12: AXL11478 | B12: AXC.ZP24B.BOO | C12: AXLE COUNTER ZP 24B BOO | D12: SE | E12: CRTE | F12: =VLOOKUP(A12,'CRTE REV.'!$A$2:$C$485,1,0) -> AXL11478 | H12: =VLOOKUP(A12,'CRTE REV.'!$A$2:$C$485,3,0) -> AXLE COUNTER ZP 24B BOO
A13: AXL11479 | B13: AXC.ZP24A.BOO | C13: AXLE COUNTER ZP 24A BOO | D13: SE | E13: CRTE | F13: =VLOOKUP(A13,'CRTE REV.'!$A$2:$C$485,1,0) -> AXL11479 | H13: =VLOOKUP(A13,'CRTE REV.'!$A$2:$C$485,3,0) -> AXLE COUNTER ZP 24A BOO
... A140: AXL11707 | B140: AXC.ZP10B.CLT | C140: AXLE COUNTER ZP 10B CLT | D140: SE | E140: CRTE | F140: =VLOOKUP(A140,'CRTE REV.'!$A$2:$C$485,1,0) -> AXL11707 | H140: =VLOOKUP(A140,'CRTE REV.'!$A$2:$C$485,3,0) -> AXLE COUNTER ZP 10B CLT
A141: BOOYK_D01-THU1-ST_MSG-SBF006 | C141: SINYAL MASUK J10 MSG | D141: SE | E141: CRTE | F141: =VLOOKUP(A141,'CRTE REV.'!$A$2:$C$485,1,0) -> #N/A | H141: =VLOOKUP(A141,'CRTE REV.'!$A$2:$C$485,3,0) -> #N/A
A142: CDA10061 | C142: CATU DAYA ER SINYAL BOO | D142: CD | E142: CRTE | F142: =VLOOKUP(A142,'CRTE REV.'!$A$2:$C$485,1,0) -> CDA10061 | H142: =VLOOKUP(A142,'CRTE REV.'!$A$2:$C$485,3,0) -> CATU DAYA ER SINYAL BOO
A143: CDA10062 | C143: CATU DAYA ER SINYAL BOP | D143: CD | E143: CRTE | F143: =VLOOKUP(A143,'CRTE REV.'!$A$2:$C$485,1,0) -> CDA10062 | H143: =VLOOKUP(A143,'CRTE REV.'!$A$2:$C$485,3,0) -> CATU DAYA ER SINYAL BOP
A144: CDA10063 | C144: CATU DAYA ER SINYAL BTT | D144: CD | E144: CRTE | F144: =VLOOKUP(A144,'CRTE REV.'!$A$2:$C$485,1,0) -> CDA10063 | H144: =VLOOKUP(A144,'CRTE REV.'!$A$2:$C$485,3,0) -> CATU DAYA ER SINYAL BTT
A145: CDA10064 | C145: CATU DAYA ER SINYAL IB COS | D145: CD | E145: CRTE | F145: =VLOOKUP(A145,'CRTE REV.'!$A$2:$C$485,1,0) -> CDA10064 | H145: =VLOOKUP(A145,'CRTE REV.'!$A$2:$C$485,3,0) -> CATU DAYA ER SINYAL IB COS
A146: CDA10065 | C146: CATU DAYA ER SINYAL MSG | D146: CD | E146: CRTE | F146: =VLOOKUP(A146,'CRTE REV.'!$A$2:$C$485,1,0) -> CDA10065 | H146: =VLOOKUP(A146,'CRTE REV.'!$A$2:$C$485,3,0) -> CATU DAYA ER SINYAL MSG
A147: CDA10066 | C147: CATU DAYA ER SINYAL IB CGB | D147: CD | E147: CRTE | F147: =VLOOKUP(A147,'CRTE REV.'!$A$2:$C$485,1,0) -> CDA10066 | H147: =VLOOKUP(A147,'CRTE REV.'!$A$2:$C$485,3,0) -> CATU DAYA ER SINYAL IB CGB
A148: CDA10068 | C148: CATU DAYA ER RADIO CIOMAS | D148: CD | E148: CRTE | F148: =VLOOKUP(A148,'CRTE REV.'!$A$2:$C$485,1,0) -> CDA10068 | H148: =VLOOKUP(A148,'CRTE REV.'!$A$2:$C$485,3,0) -> CATU DAYA ER RADIO CIOMAS
A149: CDA10069 | C149: CATU DAYA ER SINYAL CLT | D149: CD | E149: CRTE | F149: =VLOOKUP(A149,'CRTE REV.'!$A$2:$C$485,1,0) -> CDA10069 | H149: =VLOOKUP(A149,'CRTE REV.'!$A$2:$C$485,3,0) -> CATU DAYA ER SINYAL CLT
A150: CDA10136 | B150: GST.RXX.BOO | C150: GENSET ER RADIO BOO | D150: CD | E150: CRTE | F150: =VLOOKUP(A150,'CRTE REV.'!$A$2:$C$485,1,0) -> #N/A | G150: NEW | H150: =VLOOKUP(A150,'CRTE REV.'!$A$2:$C$485,3,0) -> #N/A
A151: CDA10137 | B151: GST.ER.RADIO.COS | C151: GENSET ER RADIO CS | D151: CD | E151: CRTE | F151: =VLOOKUP(A151,'CRTE REV.'!$A$2:$C$485,1,0) -> #N/A | G151: NEW | H151: =VLOOKUP(A151,'CRTE REV.'!$A$2:$C$485,3,0) -> #N/A
A152: CDA10145 | B152: GST.ER.SYL.BOO | C152: GENSET ER SINYAL BOO | D152: CD | E152: CRTE | F152: =VLOOKUP(A152,'CRTE REV.'!$A$2:$C$485,1,0) -> #N/A | G152: NEW | H152: =VLOOKUP(A152,'CRTE REV.'!$A$2:$C$485,3,0) -> #N/A
A153: CDA10146 | B153: GST.ER.RADIO.BOP | C153: GENSET ER SINYAL BOP | D153: CD | E153: CRTE | F153: =VLOOKUP(A153,'CRTE REV.'!$A$2:$C$485,1,0) -> #N/A | G153: NEW | H153: =VLOOKUP(A153,'CRTE REV.'!$A$2:$C$485,3,0) -> #N/A
A154: CDA10147 | B154: GST.ER.SYL.BTT | C154: GENSET ER SINYAL BTT | D154: CD | E154: CRTE | F154: =VLOOKUP(A154,'CRTE REV.'!$A$2:$C$485,1,0) -> #N/A | G154: NEW | H154: =VLOOKUP(A154,'CRTE REV.'!$A$2:$C$485,3,0) -> #N/A
A155: CDA10148 | B155: GST.ER.SYL.IB.CGB | C155: GENSET ER SINYAL CGB | D155: CD | E155: CRTE | F155: =VLOOKUP(A155,'CRTE REV.'!$A$2:$C$485,1,0) -> #N/A | G155: NEW | H155: =VLOOKUP(A155,'CRTE REV.'!$A$2:$C$485,3,0) -> #N/A
A156: CDA10150 | B156: GST.ER.SYL.IB.COM | C156: GENSET ER SINYAL CS | D156: CD | E156: CRTE | F156: =VLOOKUP(A156,'CRTE REV.'!$A$2:$C$485,1,0) -> #N/A | G156: NEW | H156: =VLOOKUP(A156,'CRTE REV.'!$A$2:$C$485,3,0) -> #N/A
A157: CDA10151 | B157: GST.ER.SYL.CLT | C157: GENSET ER SINYAL CLT | D157: CD | E157: CRTE | F157: =VLOOKUP(A157,'CRTE REV.'!$A$2:$C$485,1,0) -> #N/A | G157: NEW | H157: =VLOOKUP(A157,'CRTE REV.'!$A$2:$C$485,3,0) -> #N/A
A158: CDA10154 | B158: GST.ER.SYL.MSG | C158: GENSET ER SINYAL MSG | D158: CD | E158: CRTE | F158: =VLOOKUP(A158,'CRTE REV.'!$A$2:$C$485,1,0) -> #N/A | G158: NEW | H158: =VLOOKUP(A158,'CRTE REV.'!$A$2:$C$485,3,0) -> #N/A
A159: CDA10246 | B159: UPS.RXX.BOO | C159: UPS ER RADIO BOO | D159: CD | E159: CRTE | F159: =VLOOKUP(A159,'CRTE REV.'!$A$2:$C$485,1,0) -> #N/A | G159: NEW | H159: =VLOOKUP(A159,'CRTE REV.'!$A$2:$C$485,3,0) -> #N/A
A160: CDA10247 | B160: UPS.ER.RADIO.COS | C160: UPS ER RADIO CS | D160: CD | E160: CRTE | F160: =VLOOKUP(A160,'CRTE REV.'!$A$2:$C$485,1,0) -> #N/A | G160: NEW | H160: =VLOOKUP(A160,'CRTE REV.'!$A$2:$C$485,3,0) -> #N/A
A161: CDA10251 | B161: UPS.ER.SYL.BOO | C161: UPS ER SINYAL BOO | D161: CD | E161: CRTE | F161: =VLOOKUP(A161,'CRTE REV.'!$A$2:$C$485,1,0) -> #N/A | G161: NEW | H161: =VLOOKUP(A161,'CRTE REV.'!$A$2:$C$485,3,0) -> #N/A
... A176: CDA10396 | B176: BATT.ER.SYL.MSG | C176: BATTERE ER SINYAL MSG | D176: CD | E176: CRTE | F176: =VLOOKUP(A176,'CRTE REV.'!$A$2:$C$485,1,0) -> #N/A | G176: NEW | H176: =VLOOKUP(A176,'CRTE REV.'!$A$2:$C$485,3,0) -> #N/A
A177: INB10512 | B177: PC.VDU.1.BOO | C177: PANEL PELAYANAN VDU 1 BOO | D177: SE | E177: CRTE | F177: =VLOOKUP(A177,'CRTE REV.'!$A$2:$C$485,1,0) -> INB10512 | H177: =VLOOKUP(A177,'CRTE REV.'!$A$2:$C$485,3,0) -> PANEL PELAYANAN VDU 1 BOO
A178: INB10513 | B178: PC.VDU.2.BOO | C178: PANEL PELAYANAN VDU 2 BOO | D178: SE | E178: CRTE | F178: =VLOOKUP(A178,'CRTE REV.'!$A$2:$C$485,1,0) -> INB10513 | H178: =VLOOKUP(A178,'CRTE REV.'!$A$2:$C$485,3,0) -> PANEL PELAYANAN VDU 2 BOO
A179: INB10514 | B179: PC.VDU.1.BOP | C179: PANEL PELAYANAN VDU 1 BOP | D179: SE | E179: CRTE | F179: =VLOOKUP(A179,'CRTE REV.'!$A$2:$C$485,1,0) -> INB10514 | H179: =VLOOKUP(A179,'CRTE REV.'!$A$2:$C$485,3,0) -> PANEL PELAYANAN VDU 1 BOP
A180: INB10515 | B180: PC.VDU.2.BOP | C180: PANEL PELAYANAN VDU 2 BOP | D180: SE | E180: CRTE | F180: =VLOOKUP(A180,'CRTE REV.'!$A$2:$C$485,1,0) -> INB10515 | H180: =VLOOKUP(A180,'CRTE REV.'!$A$2:$C$485,3,0) -> PANEL PELAYANAN VDU 2 BOP
...

Sheet BJD-CLT
A1: PETAK JALAN (BJD-CLT)
A3: No. | B3: Functional Loc. | C3: No. K A I | D3: Description | E3: Catalog profile | F3: Jenis Perawatan | G3: Lokasi | H3: KM. | I3: LOKASI P3 | J3: Kode Cheklist
A4: 1 | B4: AXL11636 | C4: AXC.ZP207.CLT-BJD | D4: AXLE COUNTER ZP 207 CLT-BJD | E4: SE | F4: Deteksi KA | G4: BJD-CLT | H4: 46+680 | I4: BJD-CLT | J4: Deteksi KA (Siemens)
A5: 2 | B5: AXL11637 | C5: AXC.ZP206.CLT-BJD | D5: AXLE COUNTER ZP 206 CLT-BJD | E5: SE | F5: Deteksi KA | G5: BJD-CLT | H5: 46+205 | I5: BJD-CLT | J5: Deteksi KA (Siemens)
A6: 3 | B6: AXL11638 | C6: AXC.ZP205.CLT-BJD | D6: AXLE COUNTER ZP 205 CLT-BJD | E6: SE | F6: Deteksi KA | G6: BJD-CLT | H6: 45+730 | I6: BJD-CLT | J6: Deteksi KA (Siemens)
A7: 4 | B7: AXL11639 | C7: AXC.ZP102.BJD-CLT | D7: AXLE COUNTER ZP 102 BJD-CLT | E7: SE | F7: Deteksi KA | G7: BJD-CLT | H7: 45+891 | I7: BJD-CLT | J7: Deteksi KA (Siemens)
A8: 5 | B8: AXL11640 | C8: AXC.ZP101.BJD-CLT | D8: AXLE COUNTER ZP 101 BJD-CLT | E8: SE | F8: Deteksi KA | G8: BJD-CLT | H8: 46+351 | I8: BJD-CLT | J8: Deteksi KA (Siemens)
A9: Deteksi KA = 5
A10: 1 | B10: SIN11775 | C10: UB.101.BJD-CLT | D10: SINYAL ULANG BLOK UB.101 BJD-CLT | E10: SE | F10: Peraga Sinyal | G10: BJD-CLT | H10: 46+150 | I10: BJD-CLT | J10: Peraga Sinyal Elektrik
A11: 2 | B11: SIN11776 | C11: B.205.CLT-BJD | D11: SINYAL BLOK B.205 CLT-BJD | E11: SE | F11: Peraga Sinyal | G11: BJD-CLT | H11: 45+736 | I11: BJD-CLT | J11: Peraga Sinyal Elektrik
A12: 3 | B12: SIN11777 | C12: UB.205.CLT-BJD | D12: SINYAL ULANG BLOK UB.205 CLT-BJD | E12: SE | F12: Peraga Sinyal | G12: BJD-CLT | H12: 46+000 | I12: BJD-CLT | J12: Peraga Sinyal Elektrik
A13: 4 | B13: SIN11778 | C13: B.206.CLT-BJD | D13: SINYAL BLOK B.206 CLT-BJD | E13: SE | F13: Peraga Sinyal | G13: BJD-CLT | H13: 46+221 | I13: BJD-CLT | J13: Peraga Sinyal Elektrik
A14: 5 | B14: SIN11779 | C14: UB.206.CLT-BJD | D14: SINYAL ULANG BLOK UB.206 CLT-BJD | E14: SE | F14: Peraga Sinyal | G14: BJD-CLT | H14: 46+550 | I14: BJD-CLT | J14: Peraga Sinyal Elektrik
A15: 6 | B15: SIN11780 | C15: B.207.CLT-BJD | D15: SINYAL BLOK B.207 CLT-BJD | E15: SE | F15: Peraga Sinyal | G15: BJD-CLT | H15: 46+686 | I15: BJD-CLT | J15: Peraga Sinyal Elektrik
A16: 7 | B16: SIN11858 | C16: B.101.BJD-CLT | D16: SINYAL BLOK B.101 BJD-CLT | E16: SE | F16: Peraga Sinyal | G16: BJD-CLT | H16: 46+351 | I16: BJD-CLT | J16: Peraga Sinyal Elektrik
A17: 8 | B17: SIN11859 | C17: B.102.BJD-CLT | D17: SINYAL BLOK B.102 BJD-CLT | E17: SE | F17: Peraga Sinyal | G17: BJD-CLT | H17: 45+891 | I17: BJD-CLT | J17: Peraga Sinyal Elektrik
A18: 9 | B18: SIN11860 | C18: UB.102.BJD-CLT | D18: SINYAL ULANG BLOK UB.102 BJD-CLT | E18: SE | F18: Peraga Sinyal | G18: BJD-CLT | H18: 45+475 | I18: BJD-CLT | J18: Peraga Sinyal Elektrik
A19: 10 | B19: SIN11782 | C19: MJ20.CLT | D19: SINYAL MUKA MJ20 CLT | E19: SE | F19: Peraga Sinyal | G19: CLT | H19: 46+408 | I19: CLT | J19: Peraga Sinyal Elektrik
A20: Peraga Sinyal Elektrik = 10

Sheet CLT
A1: STASIUN CILEBUT
A3: No. | B3: Functional Loc. | C3: No. K A I | D3: Description | E3: Catalog profile | F3: Jenis Perawatan | G3: Lokasi | H3: KM. | I3: LOKASI P3 | J3: Kode Cheklist
A4: 1 | B4: CDA10151 | C4: GST.ER.SYL.CLT | D4: GENSET ER SINYAL CLT | E4: CD | F4: Catu Daya | G4: CLT | H4: 47+249 | I4: CLT | J4: Catudaya (40 Baterai)
A5: 2 | B5: CDA10257 | C5: UPS.ER.SYL.CLT | D5: UPS ER SINYAL CLT | E5: CD | F5: Catu Daya | G5: CLT | H5: 47+249 | I5: CLT | J5: Catudaya (40 Baterai)
A6: 3 | B6: CDA10395 | C6: BATT.ER.SYL.CLT | D6: BATTERE ER SINYAL CLT | E6: CD | F6: Catu Daya | G6: CLT | H6: 47+249 | I6: CLT | J6: Catudaya (40 Baterai)
A7: Catu Daya = 3
A8: 1 | B8: AXL11624 | C8: AXC.ZP11.CLT | D8: AXLE COUNTER ZP 11 CLT | E8: SE | F8: Deteksi KA | G8: CLT | H8: 47+133 | I8: CLT | J8: Deteksi KA (Siemens)
A9: 2 | B9: AXL11625 | C9: AXC.ZP12A.CLT | D9: AXLE COUNTER ZP 12A CLT | E9: SE | F9: Deteksi KA | G9: CLT | H9: 47+171 | I9: CLT | J9: Deteksi KA (Siemens)
A10: 3 | B10: AXL11626 | C10: AXC.ZP12B.CLT | D10: AXLE COUNTER ZP 12B CLT | E10: SE | F10: Deteksi KA | G10: CLT | H10: 47+474 | I10: CLT | J10: Deteksi KA (Siemens)
A11: 4 | B11: AXL11627 | C11: AXC.ZP13.CLT | D11: AXLE COUNTER ZP 13 CLT | E11: SE | F11: Deteksi KA | G11: CLT | H11: 47+523 | I11: CLT | J11: Deteksi KA (Siemens)
A12: 5 | B12: AXL11628 | C12: AXC.ZP14A.CLT | D12: AXLE COUNTER ZP 14A CLT | E12: SE | F12: Deteksi KA | G12: CLT | H12: 47+573 | I12: CLT | J12: Deteksi KA (Siemens)
A13: 6 | B13: AXL11629 | C13: AXC.ZP14B.CLT | D13: AXLE COUNTER ZP 14B CLT | E13: SE | F13: Deteksi KA | G13: CLT | H13: 48+103 | I13: CLT | J13: Deteksi KA (Siemens)
A14: 7 | B14: AXL11630 | C14: AXC.ZP24B.CLT | D14: AXLE COUNTER ZP 24B CLT | E14: SE | F14: Deteksi KA | G14: CLT | H14: 47+720 | I14: CLT | J14: Deteksi KA (Siemens)
A15: 8 | B15: AXL11631 | C15: AXC.ZP24A.CLT | D15: AXLE COUNTER ZP 24A CLT | E15: SE | F15: Deteksi KA | G15: CLT | H15: 47+573 | I15: CLT | J15: Deteksi KA (Siemens)
A16: 9 | B16: AXL11632 | C16: AXC.ZP22B.CLT | D16: AXLE COUNTER ZP 22B CLT | E16: SE | F16: Deteksi KA | G16: CLT | H16: 47+473 | I16: CLT | J16: Deteksi KA (Siemens)
A17: 10 | B17: AXL11633 | C17: AXC.ZP22A.CLT | D17: AXLE COUNTER ZP 22A CLT | E17: SE | F17: Deteksi KA | G17: CLT | H17: 47+155 | I17: CLT | J17: Deteksi KA (Siemens)
A18: 11 | B18: AXL11634 | C18: AXC.ZP20B.CLT | D18: AXLE COUNTER ZP 20B CLT | E18: SE | F18: Deteksi KA | G18: CLT | H18: 47+087 | I18: CLT | J18: Deteksi KA (Siemens)
A19: 12 | B19: AXL11635 | C19: AXC.ZP20A.CLT | D19: AXLE COUNTER ZP 20A CLT | E19: SE | F19: Deteksi KA | G19: CLT | H19: 46+914 | I19: CLT | J19: Deteksi KA (Siemens)
... A21: 14 | B21: AXL11707 | C21: AXC.ZP10B.CLT | D21: AXLE COUNTER ZP 10B CLT | E21: SE | F21: Deteksi KA | G21: CLT | H21: 47+087 | I21: CLT | J21: Deteksi KA (Siemens)
A22: Deteksi KA = 14
A23: 1 | B23: INB10538 | C23: IL.SIL.SAFE4000.CLT | D23: INTERLOCKING SIL SAFE 4000 CLT | E23: SE | F23: PDSE | G23: CLT | H23: 47+249 | I23: CLT | J23: Peralatan dalam sinyal elektrik
A24: 2 | B24: INB10539 | C24: DL.CLT | D24: DATA LOGGER CLT | E24: SE | F24: PDSE | G24: CLT | H24: 47+249 | I24: CLT | J24: Peralatan dalam sinyal elektrik
A25: 3 | B25: INB10541 | C25: PC.VDU.1.CLT | D25: PANEL PELAYANAN VDU 1 CLT | E25: SE | F25: PDSE | G25: CLT | H25: 47+261 | I25: CLT | J25: Peralatan dalam sinyal elektrik
A26: 4 | B26: INB10542 | C26: PC.VDU.2.CLT | D26: PANEL PELAYANAN VDU 2 CLT | E26: SE | F26: PDSE | G26: CLT | H26: 47+261 | I26: CLT | J26: Peralatan dalam sinyal elektrik
A27: 5 | B27: INB10544 | C27: PRLTN.BLOK.CLT-BJD | D27: PERALATAN BLOK CLT - BJD | E27: SE | F27: PDSE | G27: CLT | H27: 47+249 | I27: CLT | J27: Peralatan dalam sinyal elektrik
A28: 6 | B28: INB10545 | C28: PRLTN.BLOK.CLT-BOO | D28: PERALATAN BLOK CLT - BOO | E28: SE | F28: PDSE | G28: CLT | H28: 47+249 | I28: CLT | J28: Peralatan dalam sinyal elektrik
A29: 7 | B29: TRA11258 | C29: BANG.ER.SYL.CLT | D29: BANGUNAN ER SINYAL CLT | E29: BANG | F29: PDSE | G29: CLT | H29: 47+249 | I29: CLT | J29: Peralatan dalam sinyal elektrik
A30: PDSE = 7
A31: 1 | B31: INB10543 | C31: TSC.CLT | D31: PANEL DISPLAY DALWAS PERKA CLT | E31: SE | F31: PDSE | G31: CLT | H31: 47+249 | I31: CLT | J31: CTC-CTS
A32: CTC-CTS = 1
A33: 1 | B33: WSL11111 | C33: PW.21.CLT | D33: PENGGERAK WESEL W21 CLT | E33: SE | F33: Penggerak Wesel | G33: CLT | H33: 47+094 | I33: CLT | J33: Penggerak Wesel elektrik
A34: 2 | B34: WSL11112 | C34: PW.11.CLT | D34: PENGGERAK WESEL W11 CLT | E34: SE | F34: Penggerak Wesel | G34: CLT | H34: 47+166 | I34: CLT | J34: Penggerak Wesel elektrik
A35: 3 | B35: WSL11113 | C35: PW.13.CLT | D35: PENGGERAK WESEL W13 CLT | E35: SE | F35: Penggerak Wesel | G35: CLT | H35: 47+480 | I35: CLT | J35: Penggerak Wesel elektrik
A36: 4 | B36: WSL11114 | C36: PW.23.CLT | D36: PENGGERAK WESEL W23 CLT | E36: SE | F36: Penggerak Wesel | G36: CLT | H36: 47+570 | I36: CLT | J36: Penggerak Wesel elektrik
A37: Penggerak Wesel Elektrik (4x2) = 8
A38: 1 | B38: SIN11781 | C38: J20.CLT | D38: SINYAL MASUK J20 CLT | E38: SE | F38: Peraga Sinyal | G38: CLT | H38: 46+908 | I38: CLT | J38: Peraga Sinyal Elektrik
A39: 2 | B39: SIN11783 | C39: J14.CLT | D39: SINYAL MASUK J14 CLT | E39: SE | F39: Peraga Sinyal | G39: CLT | H39: 48+109 | I39: CLT | J39: Peraga Sinyal Elektrik
A40: 3 | B40: SIN11861 | C40: J10.CLT | D40: SINYAL MASUK J10 CLT | E40: SE | F40: Peraga Sinyal | G40: CLT | H40: 46+908 | I40: CLT | J40: Peraga Sinyal Elektrik
A41: 4 | B41: SIN11862 | C41: J12A.CLT | D41: SINYAL KELUAR J12A CLT | E41: SE | F41: Peraga Sinyal | G41: CLT | H41: 47+177 | I41: CLT | J41: Peraga Sinyal Elektrik
A42: 5 | B42: SIN11863 | C42: J12B.CLT | D42: SINYAL KELUAR J12B CLT | E42: SE | F42: Peraga Sinyal | G42: CLT | H42: 47+468 | I42: CLT | J42: Peraga Sinyal Elektrik
...

Sheet CLT-BOO
A1: PETAK JALAN (CLT-BOO)
A3: No. | B3: Functional Loc. | C3: No. K A I | D3: Description | E3: Catalog profile | F3: Jenis Perawatan | G3: Lokasi | H3: KM. | I3: LOKASI P3 | J3: Kode Cheklist
A4: 1 | B4: AXL11498 | C4: AXC.ZP213.BOO-CLT | D4: AXLE COUNTER ZP 213 BOO-CLT | E4: SE | F4: Deteksi KA | G4: CLT-BOO | H4: 53+650 | I4: BOO | J4: Deteksi KA (Siemens)
A5: 2 | B5: AXL11504 | C5: AXC.ZP212.BOO-CLT | D5: AXLE COUNTER ZP 212 BOO-CLT | E5: SE | F5: Deteksi KA | G5: CLT-BOO | H5: 53+239 | I5: CLT-BOO | J5: Deteksi KA (Siemens)
A6: 3 | B6: AXL11601 | C6: AXC.ZP211.BOO-CLT | D6: AXLE COUNTER ZP 211 BOO-CLT | E6: SE | F6: Deteksi KA | G6: CLT-BOO | H6: 52+824 | I6: CLT-BOO | J6: Deteksi KA (Siemens)
A7: 4 | B7: AXL11622 | C7: AXC.ZP102.CLT-BOO | D7: AXLE COUNTER ZP 102 CLT-BOO | E7: SE | F7: Deteksi KA | G7: CLT-BOO | H7: 52+645 | I7: CLT-BOO | J7: Deteksi KA (Siemens)
A8: 5 | B8: AXL11623 | C8: AXC.ZP101.CLT-BOO | D8: AXLE COUNTER ZP 101 CLT-BOO | E8: SE | F8: Deteksi KA | G8: CLT-BOO | H8: 53+352 | I8: CLT-BOO | J8: Deteksi KA (Siemens)
A9: Axle Counter 1 = 5
A10: 1 | B10: AXL11602 | C10: AXC.ZP210.BOO-CLT | D10: AXLE COUNTER ZP 210 BOO-CLT | E10: SE | F10: Deteksi KA | G10: CLT-BOO | H10: 52+381 | I10: CLT-BOO | J10: Deteksi KA (Siemens)
A11: 2 | B11: AXL11603 | C11: AXC.ZP209.BOO-CLT | D11: AXLE COUNTER ZP 209 BOO-CLT | E11: SE | F11: Deteksi KA | G11: CLT-BOO | H11: 51+921 | I11: CLT-BOO | J11: Deteksi KA (Siemens)
A12: 3 | B12: AXL11604 | C12: AXC.ZP208.BOO-CLT | D12: AXLE COUNTER ZP 208 BOO-CLT | E12: SE | F12: Deteksi KA | G12: CLT-BOO | H12: 51+461 | I12: CLT-BOO | J12: Deteksi KA (Siemens)
A13: 4 | B13: AXL11619 | C13: AXC.ZP105.CLT-BOO | D13: AXLE COUNTER ZP 105 CLT-BOO | E13: SE | F13: Deteksi KA | G13: CLT-BOO | H13: 51+512 | I13: CLT-BOO | J13: Deteksi KA (Siemens)
A14: 5 | B14: AXL11620 | C14: AXC.ZP104.CLT-BOO | D14: AXLE COUNTER ZP 104 CLT-BOO | E14: SE | F14: Deteksi KA | G14: CLT-BOO | H14: 51,972 | I14: CLT-BOO | J14: Deteksi KA (Siemens)
A15: 6 | B15: AXL11621 | C15: AXC.ZP103.CLT-BOO | D15: AXLE COUNTER ZP 103 CLT-BOO | E15: SE | F15: Deteksi KA | G15: CLT-BOO | H15: 52+432 | I15: CLT-BOO | J15: Deteksi KA (Siemens)
A16: Axle Counter 2 = 6
A17: 1 | B17: AXL11605 | C17: AXC.ZP207.BOO-CLT | D17: AXLE COUNTER ZP 207 BOO-CLT | E17: SE | F17: Deteksi KA | G17: CLT-BOO | H17: 51+001 | I17: CLT-BOO | J17: Deteksi KA (Siemens)
A18: 2 | B18: AXL11606 | C18: AXC.ZP206.BOO-CLT | D18: AXLE COUNTER ZP 206 BOO-CLT | E18: SE | F18: Deteksi KA | G18: CLT-BOO | H18: 50+541 | I18: CLT-BOO | J18: Deteksi KA (Siemens)
A19: 3 | B19: AXL11607 | C19: AXC.ZP205.BOO-CLT | D19: AXLE COUNTER ZP 205 BOO-CLT | E19: SE | F19: Deteksi KA | G19: CLT-BOO | H19: 50+081 | I19: CLT-BOO | J19: Deteksi KA (Siemens)
A20: 4 | B20: AXL11608 | C20: AXC.ZP204.BOO-CLT | D20: AXLE COUNTER ZP 204 BOO-CLT | E20: SE | F20: Deteksi KA | G20: CLT-BOO | H20: 49+621 | I20: CLT-BOO | J20: Deteksi KA (Siemens)
A21: 5 | B21: AXL11615 | C21: AXC.ZP109.CLT-BOO | D21: AXLE COUNTER ZP 109 CLT-BOO | E21: SE | F21: Deteksi KA | G21: CLT-BOO | H21: 49+499 | I21: CLT-BOO | J21: Deteksi KA (Siemens)
A22: 6 | B22: AXL11616 | C22: AXC.ZP108.CLT-BOO | D22: AXLE COUNTER ZP 108 CLT-BOO | E22: SE | F22: Deteksi KA | G22: CLT-BOO | H22: 49+959 | I22: CLT-BOO | J22: Deteksi KA (Siemens)
A23: 7 | B23: AXL11617 | C23: AXC.ZP107.CLT-BOO | D23: AXLE COUNTER ZP 107 CLT-BOO | E23: SE | F23: Deteksi KA | G23: CLT-BOO | H23: 50+592 | I23: CLT-BOO | J23: Deteksi KA (Siemens)
A24: 8 | B24: AXL11618 | C24: AXC.ZP106.CLT-BOO | D24: AXLE COUNTER ZP 106 CLT-BOO | E24: SE | F24: Deteksi KA | G24: CLT-BOO | H24: 51+052 | I24: CLT-BOO | J24: Deteksi KA (Siemens)
A25: Axle Counter 3 = 8
A26: 1 | B26: AXL11609 | C26: AXC.ZP203.BOO-CLT | D26: AXLE COUNTER ZP 203 BOO-CLT | E26: SE | F26: Deteksi KA | G26: CLT-BOO | H26: 49+161 | I26: CLT-BOO | J26: Deteksi KA (Siemens)
A27: 2 | B27: AXL11610 | C27: AXC.ZP202.BOO-CLT | D27: AXLE COUNTER ZP 202 BOO-CLT | E27: SE | F27: Deteksi KA | G27: CLT-BOO | H27: 48+701 | I27: CLT-BOO | J27: Deteksi KA (Siemens)
A28: 3 | B28: AXL11611 | C28: AXC.ZP201.BOO-CLT | D28: AXLE COUNTER ZP 201 BOO-CLT | E28: SE | F28: Deteksi KA | G28: CLT-BOO | H28: 48+260 | I28: CLT-BOO | J28: Deteksi KA (Siemens)
A29: 4 | B29: AXL11612 | C29: AXC.ZP112.CLT-BOO | D29: AXLE COUNTER ZP 112 CLT-BOO | E29: SE | F29: Deteksi KA | G29: CLT-BOO | H29: 48+119 | I29: CLT-BOO | J29: Deteksi KA (Siemens)
